Workbook
Name CorrelationScenario: Misc!$B$3:$B$6

Sheet BIS Data
B1: GIRR
C3: RiskWeight | D3: RW Lite | E3: RW regular | G3: Parameter | H3: Value | I3: RW Lite | J3: RW regular | L3: Reduced Ccy
G4: Theta | H4: 0.03 | I4: 0.03 | J4: 0.03 | L4: EUR
B5: 0.25 | C5: =IF('Consolidated View'!$C$2="Lite",D5,E5) -> 0.024 | D5: 0.05 | E5: 0.024 | G5: CSM | H5: =IF('Consolidated View'!$C$2="Lite",I5,J5) -> 1 | I5: ='Consolidated View'!$D$2 -> 1 | J5: ='Consolidated View'!$D$2 -> 1 | L5: USD
B6: 0.5 | C6: =IF('Consolidated View'!$C$2="Lite",D6,E6) -> 0.024 | D6: 0.05 | E6: 0.024 | G6: Gamma | H6: 0.5 | I6: 0.5 | J6: 0.5 | L6: GBP
B7: 1 | C7: =IF('Consolidated View'!$C$2="Lite",D7,E7) -> 0.0225 | D7: 0.05 | E7: 0.0225 | G7: Min corr. | H7: =IF('Consolidated View'!$C$2="Lite",I7,J7) -> 0.4 | I7: 0.4 | J7: 0.4 | L7: AUD
B8: 2 | C8: =IF('Consolidated View'!$C$2="Lite",D8,E8) -> 0.0188 | D8: 0.05 | E8: 0.0188 | G8: Reduced Ccy | H8: =IF('Consolidated View'!$C$2="Lite",I8,J8) -> 1.4142136 | I8: 1 | J8: =SQRT(2) -> 1.4142136 | L8: JPY
B9: 3 | C9: =IF('Consolidated View'!$C$2="Lite",D9,E9) -> 0.0173 | D9: 0.05 | E9: 0.0173 | L9: SEK
B10: 5 | C10: =IF('Consolidated View'!$C$2="Lite",D10,E10) -> 0.015 | D10: 0.05 | E10: 0.015 | L10: CAD
B11: 10 | C11: =IF('Consolidated View'!$C$2="Lite",D11,E11) -> 0.015 | D11: 0.05 | E11: 0.015
B12: 15 | C12: =IF('Consolidated View'!$C$2="Lite",D12,E12) -> 0.015 | D12: 0.05 | E12: 0.015
B13: 20 | C13: =IF('Consolidated View'!$C$2="Lite",D13,E13) -> 0.015 | D13: 0.05 | E13: 0.015
B14: 30 | C14: =IF('Consolidated View'!$C$2="Lite",D14,E14) -> 0.015 | D14: 0.05 | E14: 0.015
B16: Cross Tenor Correlations Curves Used
C17: 0.25 | D17: 0.5 | E17: 1 | F17: 2 | G17: 3 | H17: 5 | I17: 10 | J17: 15 | K17: 20 | L17: 30
B18: 0.25 | C18: =IF('Consolidated View'!$C$2="Lite",C44,C31) -> 1 | D18: =IF('Consolidated View'!$C$2="Lite",D44,D31) -> 0.97044553 | E18: =IF('Consolidated View'!$C$2="Lite",E44,E31) -> 0.91393119 | F18: =IF('Consolidated View'!$C$2="Lite",F44,F31) -> 0.81058425 | G18: =IF('Consolidated View'!$C$2="Lite",G44,G31) -> 0.71892373 | H18: =IF('Consolidated View'!$C$2="Lite",H44,H31) -> 0.56552544 | I18: =IF('Consolidated View'!$C$2="Lite",I44,I31) -> 0.4 | J18: =IF('Consolidated View'!$C$2="Lite",J44,J31) -> 0.4 | ... L18: =IF('Consolidated View'!$C$2="Lite",L44,L31) -> 0.4
B19: 0.5 | C19: =IF('Consolidated View'!$C$2="Lite",C45,C32) -> 0.97044553 | D19: =IF('Consolidated View'!$C$2="Lite",D45,D32) -> 1 | E19: =IF('Consolidated View'!$C$2="Lite",E45,E32) -> 0.97044553 | F19: =IF('Consolidated View'!$C$2="Lite",F45,F32) -> 0.91393119 | G19: =IF('Consolidated View'!$C$2="Lite",G45,G32) -> 0.86070798 | H19: =IF('Consolidated View'!$C$2="Lite",H45,H32) -> 0.76337949 | I19: =IF('Consolidated View'!$C$2="Lite",I45,I32) -> 0.56552544 | J19: =IF('Consolidated View'!$C$2="Lite",J45,J32) -> 0.41895155 | ... L19: =IF('Consolidated View'!$C$2="Lite",L45,L32) -> 0.4
B20: 1 | C20: =IF('Consolidated View'!$C$2="Lite",C46,C33) -> 0.91393119 | D20: =IF('Consolidated View'!$C$2="Lite",D46,D33) -> 0.97044553 | E20: =IF('Consolidated View'!$C$2="Lite",E46,E33) -> 1 | F20: =IF('Consolidated View'!$C$2="Lite",F46,F33) -> 0.97044553 | G20: =IF('Consolidated View'!$C$2="Lite",G46,G33) -> 0.94176453 | H20: =IF('Consolidated View'!$C$2="Lite",H46,H33) -> 0.88692044 | I20: =IF('Consolidated View'!$C$2="Lite",I46,I33) -> 0.76337949 | J20: =IF('Consolidated View'!$C$2="Lite",J46,J33) -> 0.65704682 | ... L20: =IF('Consolidated View'!$C$2="Lite",L46,L33) -> 0.41895155
B21: 2 | C21: =IF('Consolidated View'!$C$2="Lite",C47,C34) -> 0.81058425 | D21: =IF('Consolidated View'!$C$2="Lite",D47,D34) -> 0.91393119 | E21: =IF('Consolidated View'!$C$2="Lite",E47,E34) -> 0.97044553 | F21: =IF('Consolidated View'!$C$2="Lite",F47,F34) -> 1 | G21: =IF('Consolidated View'!$C$2="Lite",G47,G34) -> 0.98511194 | H21: =IF('Consolidated View'!$C$2="Lite",H47,H34) -> 0.95599748 | I21: =IF('Consolidated View'!$C$2="Lite",I47,I34) -> 0.88692044 | J21: =IF('Consolidated View'!$C$2="Lite",J47,J34) -> 0.82283466 | ... L21: =IF('Consolidated View'!$C$2="Lite",L47,L34) -> 0.65704682
B22: 3 | C22: =IF('Consolidated View'!$C$2="Lite",C48,C35) -> 0.71892373 | D22: =IF('Consolidated View'!$C$2="Lite",D48,D35) -> 0.86070798 | E22: =IF('Consolidated View'!$C$2="Lite",E48,E35) -> 0.94176453 | F22: =IF('Consolidated View'!$C$2="Lite",F48,F35) -> 0.98511194 | G22: =IF('Consolidated View'!$C$2="Lite",G48,G35) -> 1 | H22: =IF('Consolidated View'!$C$2="Lite",H48,H35) -> 0.98019867 | I22: =IF('Consolidated View'!$C$2="Lite",I48,I35) -> 0.93239382 | J22: =IF('Consolidated View'!$C$2="Lite",J48,J35) -> 0.88692044 | ... L22: =IF('Consolidated View'!$C$2="Lite",L48,L35) -> 0.76337949
B23: 5 | C23: =IF('Consolidated View'!$C$2="Lite",C49,C36) -> 0.56552544 | D23: =IF('Consolidated View'!$C$2="Lite",D49,D36) -> 0.76337949 | E23: =IF('Consolidated View'!$C$2="Lite",E49,E36) -> 0.88692044 | F23: =IF('Consolidated View'!$C$2="Lite",F49,F36) -> 0.95599748 | G23: =IF('Consolidated View'!$C$2="Lite",G49,G36) -> 0.98019867 | H23: =IF('Consolidated View'!$C$2="Lite",H49,H36) -> 1 | I23: =IF('Consolidated View'!$C$2="Lite",I49,I36) -> 0.97044553 | J23: =IF('Consolidated View'!$C$2="Lite",J49,J36) -> 0.94176453 | ... L23: =IF('Consolidated View'!$C$2="Lite",L49,L36) -> 0.86070798
B24: 10 | C24: =IF('Consolidated View'!$C$2="Lite",C50,C37) -> 0.4 | D24: =IF('Consolidated View'!$C$2="Lite",D50,D37) -> 0.56552544 | E24: =IF('Consolidated View'!$C$2="Lite",E50,E37) -> 0.76337949 | F24: =IF('Consolidated View'!$C$2="Lite",F50,F37) -> 0.88692044 | G24: =IF('Consolidated View'!$C$2="Lite",G50,G37) -> 0.93239382 | H24: =IF('Consolidated View'!$C$2="Lite",H50,H37) -> 0.97044553 | I24: =IF('Consolidated View'!$C$2="Lite",I50,I37) -> 1 | J24: =IF('Consolidated View'!$C$2="Lite",J50,J37) -> 0.98511194 | ... L24: =IF('Consolidated View'!$C$2="Lite",L50,L37) -> 0.94176453
B25: 15 | C25: =IF('Consolidated View'!$C$2="Lite",C51,C38) -> 0.4 | D25: =IF('Consolidated View'!$C$2="Lite",D51,D38) -> 0.41895155 | E25: =IF('Consolidated View'!$C$2="Lite",E51,E38) -> 0.65704682 | F25: =IF('Consolidated View'!$C$2="Lite",F51,F38) -> 0.82283466 | G25: =IF('Consolidated View'!$C$2="Lite",G51,G38) -> 0.88692044 | H25: =IF('Consolidated View'!$C$2="Lite",H51,H38) -> 0.94176453 | I25: =IF('Consolidated View'!$C$2="Lite",I51,I38) -> 0.98511194 | J25: =IF('Consolidated View'!$C$2="Lite",J51,J38) -> 1 | ... L25: =IF('Consolidated View'!$C$2="Lite",L51,L38) -> 0.97044553
B26: 20 | C26: =IF('Consolidated View'!$C$2="Lite",C52,C39) -> 0.4 | D26: =IF('Consolidated View'!$C$2="Lite",D52,D39) -> 0.4 | E26: =IF('Consolidated View'!$C$2="Lite",E52,E39) -> 0.56552544 | F26: =IF('Consolidated View'!$C$2="Lite",F52,F39) -> 0.76337949 | G26: =IF('Consolidated View'!$C$2="Lite",G52,G39) -> 0.84366482 | H26: =IF('Consolidated View'!$C$2="Lite",H52,H39) -> 0.91393119 | I26: =IF('Consolidated View'!$C$2="Lite",I52,I39) -> 0.97044553 | J26: =IF('Consolidated View'!$C$2="Lite",J52,J39) -> 0.99004983 | ... L26: =IF('Consolidated View'!$C$2="Lite",L52,L39) -> 0.98511194
B27: 30 | C27: =IF('Consolidated View'!$C$2="Lite",C53,C40) -> 0.4 | D27: =IF('Consolidated View'!$C$2="Lite",D53,D40) -> 0.4 | E27: =IF('Consolidated View'!$C$2="Lite",E53,E40) -> 0.41895155 | F27: =IF('Consolidated View'!$C$2="Lite",F53,F40) -> 0.65704682 | G27: =IF('Consolidated View'!$C$2="Lite",G53,G40) -> 0.76337949 | H27: =IF('Consolidated View'!$C$2="Lite",H53,H40) -> 0.86070798 | I27: =IF('Consolidated View'!$C$2="Lite",I53,I40) -> 0.94176453 | J27: =IF('Consolidated View'!$C$2="Lite",J53,J40) -> 0.97044553 | ... L27: =IF('Consolidated View'!$C$2="Lite",L53,L40) -> 1
B29: Regular Correlations - Functional Form Exponentially Decaying
C30: 0.25 | D30: 0.5 | E30: 1 | F30: 2 | G30: 3 | H30: 5 | I30: 10 | J30: 15 | K30: 20 | L30: 30
B31: 0.25 | C31: =MIN(1,MAX(-1,MAX(EXP(-$H$4*ABS($B31-C$17)/(MIN($B31,C$17))),$H$7))) -> 1 | D31: =MIN(1,MAX(-1,MAX(EXP(-$H$4*ABS($B31-D$17)/(MIN($B31,D$17))),$H$7))) -> 0.97044553 | E31: =MIN(1,MAX(-1,MAX(EXP(-$H$4*ABS($B31-E$17)/(MIN($B31,E$17))),$H$7))) -> 0.91393119 | F31: =MIN(1,MAX(-1,MAX(EXP(-$H$4*ABS($B31-F$17)/(MIN($B31,F$17))),$H$7))) -> 0.81058425 | G31: =MIN(1,MAX(-1,MAX(EXP(-$H$4*ABS($B31-G$17)/(MIN($B31,G$17))),$H$7))) -> 0.71892373 | H31: =MIN(1,MAX(-1,MAX(EXP(-$H$4*ABS($B31-H$17)/(MIN($B31,H$17))),$H$7))) -> 0.56552544 | I31: =MIN(1,MAX(-1,MAX(EXP(-$H$4*ABS($B31-I$17)/(MIN($B31,I$17))),$H$7))) -> 0.4 | J31: =MIN(1,MAX(-1,MAX(EXP(-$H$4*ABS($B31-J$17)/(MIN($B31,J$17))),$H$7))) -> 0.4 | ... L31: =MIN(1,MAX(-1,MAX(EXP(-$H$4*ABS($B31-L$17)/(MIN($B31,L$17))),$H$7))) -> 0.4
B32: 0.5 | C32: =MIN(1,MAX(-1,MAX(EXP(-$H$4*ABS($B32-C$17)/(MIN($B32,C$17))),$H$7))) -> 0.97044553 | D32: =MIN(1,MAX(-1,MAX(EXP(-$H$4*ABS($B32-D$17)/(MIN($B32,D$17))),$H$7))) -> 1 | E32: =MIN(1,MAX(-1,MAX(EXP(-$H$4*ABS($B32-E$17)/(MIN($B32,E$17))),$H$7))) -> 0.97044553 | F32: =MIN(1,MAX(-1,MAX(EXP(-$H$4*ABS($B32-F$17)/(MIN($B32,F$17))),$H$7))) -> 0.91393119 | G32: =MIN(1,MAX(-1,MAX(EXP(-$H$4*ABS($B32-G$17)/(MIN($B32,G$17))),$H$7))) -> 0.86070798 | H32: =MIN(1,MAX(-1,MAX(EXP(-$H$4*ABS($B32-H$17)/(MIN($B32,H$17))),$H$7))) -> 0.76337949 | I32: =MIN(1,MAX(-1,MAX(EXP(-$H$4*ABS($B32-I$17)/(MIN($B32,I$17))),$H$7))) -> 0.56552544 | J32: =MIN(1,MAX(-1,MAX(EXP(-$H$4*ABS($B32-J$17)/(MIN($B32,J$17))),$H$7))) -> 0.41895155 | ... L32: =MIN(1,MAX(-1,MAX(EXP(-$H$4*ABS($B32-L$17)/(MIN($B32,L$17))),$H$7))) -> 0.4
B33: 1 | C33: =MIN(1,MAX(-1,MAX(EXP(-$H$4*ABS($B33-C$17)/(MIN($B33,C$17))),$H$7))) -> 0.91393119 | D33: =MIN(1,MAX(-1,MAX(EXP(-$H$4*ABS($B33-D$17)/(MIN($B33,D$17))),$H$7))) -> 0.97044553 | E33: =MIN(1,MAX(-1,MAX(EXP(-$H$4*ABS($B33-E$17)/(MIN($B33,E$17))),$H$7))) -> 1 | F33: =MIN(1,MAX(-1,MAX(EXP(-$H$4*ABS($B33-F$17)/(MIN($B33,F$17))),$H$7))) -> 0.97044553 | G33: =MIN(1,MAX(-1,MAX(EXP(-$H$4*ABS($B33-G$17)/(MIN($B33,G$17))),$H$7))) -> 0.94176453 | H33: =MIN(1,MAX(-1,MAX(EXP(-$H$4*ABS($B33-H$17)/(MIN($B33,H$17))),$H$7))) -> 0.88692044 | I33: =MIN(1,MAX(-1,MAX(EXP(-$H$4*ABS($B33-I$17)/(MIN($B33,I$17))),$H$7))) -> 0.76337949 | J33: =MIN(1,MAX(-1,MAX(EXP(-$H$4*ABS($B33-J$17)/(MIN($B33,J$17))),$H$7))) -> 0.65704682 | ... L33: =MIN(1,MAX(-1,MAX(EXP(-$H$4*ABS($B33-L$17)/(MIN($B33,L$17))),$H$7))) -> 0.41895155
B34: 2 | C34: =MIN(1,MAX(-1,MAX(EXP(-$H$4*ABS($B34-C$17)/(MIN($B34,C$17))),$H$7))) -> 0.81058425 | D34: =MIN(1,MAX(-1,MAX(EXP(-$H$4*ABS($B34-D$17)/(MIN($B34,D$17))),$H$7))) -> 0.91393119 | E34: =MIN(1,MAX(-1,MAX(EXP(-$H$4*ABS($B34-E$17)/(MIN($B34,E$17))),$H$7))) -> 0.97044553 | F34: =MIN(1,MAX(-1,MAX(EXP(-$H$4*ABS($B34-F$17)/(MIN($B34,F$17))),$H$7))) -> 1 | G34: =MIN(1,MAX(-1,MAX(EXP(-$H$4*ABS($B34-G$17)/(MIN($B34,G$17))),$H$7))) -> 0.98511194 | H34: =MIN(1,MAX(-1,MAX(EXP(-$H$4*ABS($B34-H$17)/(MIN($B34,H$17))),$H$7))) -> 0.95599748 | I34: =MIN(1,MAX(-1,MAX(EXP(-$H$4*ABS($B34-I$17)/(MIN($B34,I$17))),$H$7))) -> 0.88692044 | J34: =MIN(1,MAX(-1,MAX(EXP(-$H$4*ABS($B34-J$17)/(MIN($B34,J$17))),$H$7))) -> 0.82283466 | ... L34: =MIN(1,MAX(-1,MAX(EXP(-$H$4*ABS($B34-L$17)/(MIN($B34,L$17))),$H$7))) -> 0.65704682
B35: 3 | C35: =MIN(1,MAX(-1,MAX(EXP(-$H$4*ABS($B35-C$17)/(MIN($B35,C$17))),$H$7))) -> 0.71892373 | D35: =MIN(1,MAX(-1,MAX(EXP(-$H$4*ABS($B35-D$17)/(MIN($B35,D$17))),$H$7))) -> 0.86070798 | E35: =MIN(1,MAX(-1,MAX(EXP(-$H$4*ABS($B35-E$17)/(MIN($B35,E$17))),$H$7))) -> 0.94176453 | F35: =MIN(1,MAX(-1,MAX(EXP(-$H$4*ABS($B35-F$17)/(MIN($B35,F$17))),$H$7))) -> 0.98511194 | G35: =MIN(1,MAX(-1,MAX(EXP(-$H$4*ABS($B35-G$17)/(MIN($B35,G$17))),$H$7))) -> 1 | H35: =MIN(1,MAX(-1,MAX(EXP(-$H$4*ABS($B35-H$17)/(MIN($B35,H$17))),$H$7))) -> 0.98019867 | I35: =MIN(1,MAX(-1,MAX(EXP(-$H$4*ABS($B35-I$17)/(MIN($B35,I$17))),$H$7))) -> 0.93239382 | J35: =MIN(1,MAX(-1,MAX(EXP(-$H$4*ABS($B35-J$17)/(MIN($B35,J$17))),$H$7))) -> 0.88692044 | ... L35: =MIN(1,MAX(-1,MAX(EXP(-$H$4*ABS($B35-L$17)/(MIN($B35,L$17))),$H$7))) -> 0.76337949
B36: 5 | C36: =MIN(1,MAX(-1,MAX(EXP(-$H$4*ABS($B36-C$17)/(MIN($B36,C$17))),$H$7))) -> 0.56552544 | D36: =MIN(1,MAX(-1,MAX(EXP(-$H$4*ABS($B36-D$17)/(MIN($B36,D$17))),$H$7))) -> 0.76337949 | E36: =MIN(1,MAX(-1,MAX(EXP(-$H$4*ABS($B36-E$17)/(MIN($B36,E$17))),$H$7))) -> 0.88692044 | F36: =MIN(1,MAX(-1,MAX(EXP(-$H$4*ABS($B36-F$17)/(MIN($B36,F$17))),$H$7))) -> 0.95599748 | G36: =MIN(1,MAX(-1,MAX(EXP(-$H$4*ABS($B36-G$17)/(MIN($B36,G$17))),$H$7))) -> 0.98019867 | H36: =MIN(1,MAX(-1,MAX(EXP(-$H$4*ABS($B36-H$17)/(MIN($B36,H$17))),$H$7))) -> 1 | I36: =MIN(1,MAX(-1,MAX(EXP(-$H$4*ABS($B36-I$17)/(MIN($B36,I$17))),$H$7))) -> 0.97044553 | J36: =MIN(1,MAX(-1,MAX(EXP(-$H$4*ABS($B36-J$17)/(MIN($B36,J$17))),$H$7))) -> 0.94176453 | ... L36: =MIN(1,MAX(-1,MAX(EXP(-$H$4*ABS($B36-L$17)/(MIN($B36,L$17))),$H$7))) -> 0.86070798
B37: 10 | C37: =MIN(1,MAX(-1,MAX(EXP(-$H$4*ABS($B37-C$17)/(MIN($B37,C$17))),$H$7))) -> 0.4 | D37: =MIN(1,MAX(-1,MAX(EXP(-$H$4*ABS($B37-D$17)/(MIN($B37,D$17))),$H$7))) -> 0.56552544 | E37: =MIN(1,MAX(-1,MAX(EXP(-$H$4*ABS($B37-E$17)/(MIN($B37,E$17))),$H$7))) -> 0.76337949 | F37: =MIN(1,MAX(-1,MAX(EXP(-$H$4*ABS($B37-F$17)/(MIN($B37,F$17))),$H$7))) -> 0.88692044 | G37: =MIN(1,MAX(-1,MAX(EXP(-$H$4*ABS($B37-G$17)/(MIN($B37,G$17))),$H$7))) -> 0.93239382 | H37: =MIN(1,MAX(-1,MAX(EXP(-$H$4*ABS($B37-H$17)/(MIN($B37,H$17))),$H$7))) -> 0.97044553 | I37: =MIN(1,MAX(-1,MAX(EXP(-$H$4*ABS($B37-I$17)/(MIN($B37,I$17))),$H$7))) -> 1 | J37: =MIN(1,MAX(-1,MAX(EXP(-$H$4*ABS($B37-J$17)/(MIN($B37,J$17))),$H$7))) -> 0.98511194 | ... L37: =MIN(1,MAX(-1,MAX(EXP(-$H$4*ABS($B37-L$17)/(MIN($B37,L$17))),$H$7))) -> 0.94176453
B38: 15 | C38: =MIN(1,MAX(-1,MAX(EXP(-$H$4*ABS($B38-C$17)/(MIN($B38,C$17))),$H$7))) -> 0.4 | D38: =MIN(1,MAX(-1,MAX(EXP(-$H$4*ABS($B38-D$17)/(MIN($B38,D$17))),$H$7))) -> 0.41895155 | E38: =MIN(1,MAX(-1,MAX(EXP(-$H$4*ABS($B38-E$17)/(MIN($B38,E$17))),$H$7))) -> 0.65704682 | F38: =MIN(1,MAX(-1,MAX(EXP(-$H$4*ABS($B38-F$17)/(MIN($B38,F$17))),$H$7))) -> 0.82283466 | G38: =MIN(1,MAX(-1,MAX(EXP(-$H$4*ABS($B38-G$17)/(MIN($B38,G$17))),$H$7))) -> 0.88692044 | H38: =MIN(1,MAX(-1,MAX(EXP(-$H$4*ABS($B38-H$17)/(MIN($B38,H$17))),$H$7))) -> 0.94176453 | I38: =MIN(1,MAX(-1,MAX(EXP(-$H$4*ABS($B38-I$17)/(MIN($B38,I$17))),$H$7))) -> 0.98511194 | J38: =MIN(1,MAX(-1,MAX(EXP(-$H$4*ABS($B38-J$17)/(MIN($B38,J$17))),$H$7))) -> 1 | ... L38: =MIN(1,MAX(-1,MAX(EXP(-$H$4*ABS($B38-L$17)/(MIN($B38,L$17))),$H$7))) -> 0.97044553
B39: 20 | C39: =MIN(1,MAX(-1,MAX(EXP(-$H$4*ABS($B39-C$17)/(MIN($B39,C$17))),$H$7))) -> 0.4 | D39: =MIN(1,MAX(-1,MAX(EXP(-$H$4*ABS($B39-D$17)/(MIN($B39,D$17))),$H$7))) -> 0.4 | E39: =MIN(1,MAX(-1,MAX(EXP(-$H$4*ABS($B39-E$17)/(MIN($B39,E$17))),$H$7))) -> 0.56552544 | F39: =MIN(1,MAX(-1,MAX(EXP(-$H$4*ABS($B39-F$17)/(MIN($B39,F$17))),$H$7))) -> 0.76337949 | G39: =MIN(1,MAX(-1,MAX(EXP(-$H$4*ABS($B39-G$17)/(MIN($B39,G$17))),$H$7))) -> 0.84366482 | H39: =MIN(1,MAX(-1,MAX(EXP(-$H$4*ABS($B39-H$17)/(MIN($B39,H$17))),$H$7))) -> 0.91393119 | I39: =MIN(1,MAX(-1,MAX(EXP(-$H$4*ABS($B39-I$17)/(MIN($B39,I$17))),$H$7))) -> 0.97044553 | J39: =MIN(1,MAX(-1,MAX(EXP(-$H$4*ABS($B39-J$17)/(MIN($B39,J$17))),$H$7))) -> 0.99004983 | ... L39: =MIN(1,MAX(-1,MAX(EXP(-$H$4*ABS($B39-L$17)/(MIN($B39,L$17))),$H$7))) -> 0.98511194
B40: 30 | C40: =MIN(1,MAX(-1,MAX(EXP(-$H$4*ABS($B40-C$17)/(MIN($B40,C$17))),$H$7))) -> 0.4 | D40: =MIN(1,MAX(-1,MAX(EXP(-$H$4*ABS($B40-D$17)/(MIN($B40,D$17))),$H$7))) -> 0.4 | E40: =MIN(1,MAX(-1,MAX(EXP(-$H$4*ABS($B40-E$17)/(MIN($B40,E$17))),$H$7))) -> 0.41895155 | F40: =MIN(1,MAX(-1,MAX(EXP(-$H$4*ABS($B40-F$17)/(MIN($B40,F$17))),$H$7))) -> 0.65704682 | G40: =MIN(1,MAX(-1,MAX(EXP(-$H$4*ABS($B40-G$17)/(MIN($B40,G$17))),$H$7))) -> 0.76337949 | H40: =MIN(1,MAX(-1,MAX(EXP(-$H$4*ABS($B40-H$17)/(MIN($B40,H$17))),$H$7))) -> 0.86070798 | I40: =MIN(1,MAX(-1,MAX(EXP(-$H$4*ABS($B40-I$17)/(MIN($B40,I$17))),$H$7))) -> 0.94176453 | J40: =MIN(1,MAX(-1,MAX(EXP(-$H$4*ABS($B40-J$17)/(MIN($B40,J$17))),$H$7))) -> 0.97044553 | ... L40: =MIN(1,MAX(-1,MAX(EXP(-$H$4*ABS($B40-L$17)/(MIN($B40,L$17))),$H$7))) -> 1
B42: Light Correlations
C43: 0.25 | D43: 0.5 | E43: 1 | F43: 2 | G43: 3 | H43: 5 | I43: 10 | J43: 15 | K43: 20 | L43: 30
B44: 0.25 | C44: 1 | D44: 1 | E44: 1 | F44: 1 | G44: 1 | H44: 1 | I44: 0.2 | J44: 0.2 | K44: 0.2 | L44: 0.2
...

Sheet Consolidated View
B2: Correlation scenario | C2: Medium | D2: {=_xlfn.IFS(C2 = "Medium", 1, C2 = "Low", 0.75, C2 = "High", 1.25, C2 = "Lite", 1)} -> 1
B3: Charge for Interest Rate Delta | C3: ='GIRR Delta Aggregations'!C16 -> 4964393.6
B4: Total FRTB Charge | C4: =C3 -> 4964393.6
B6: Example use case is an at-the-money SOFR interest rate swap.
B7: Calculations are done as of March 21st, 2024
B9: 5Y SOFR swap collateralized in USD as of March 21, 2024 | H9: SOFR Curve | L9: Generates Zero Curve (calculated outside of Excel)
B11: Start Date | C11: 45376 | D11: Notional | E11: 100000000 | I11: Overnight | J11: 5.48 | L11: Curve Point | M11: #Days | N11: Zero Rate | O11: Discount Factor
B12: End Date | C12: 47202 | H12: SOFR Swap | I12: 3 Month | J12: 5.22275 | L12: 45373 | M12: 1 | N12: 5.5556883 | O12: 0.9998478
H13: SOFR Swap | I13: 6 Month | J13: 5.1452 | L13: 45376 | M13: 4 | N13: 5.5556883 | O13: 0.99939134
B14: Pay Side | E14: Receive Side | H14: SOFR Swap | I14: 9 Month | J14: 5.08691 | L14: 45470 | M14: 98 | N14: 5.269969 | O14: 0.98595013
B15: Ccy | C15: USD | E15: Ccy | F15: USD | H15: SOFR Swap | I15: 1 Year | J15: 5 | L15: 45562 | M15: 190 | N15: 5.155741 | O15: 0.97351884
B16: Index | C16: FIXED | E16: Index | F16: SOFR | H16: SOFR Swap | I16: 18 Month | J16: 4.71402 | L16: 45656 | M16: 284 | N16: 5.061861 | O16: 0.96138008
B17: Rate | C17: 0.04013 | E17: Rate | F17: NA | H17: SOFR Swap | I17: 2 Year | J17: 4.5216 | L17: 45743 | M17: 371 | N17: 4.9486808 | O17: 0.95094382
B18: Spread | C18: NA | E18: Spread | F18: 0 | H18: SOFR Swap | I18: 3 Year | J18: 4.2359 | L18: 45929 | M18: 557 | N18: 4.6794341 | O18: 0.93108059
B19: Basis | C19: 30/360 | E19: Basis | F19: A/360 | H19: SOFR Swap | I19: 4 Year | J19: 4.1022 | L19: 46108 | M19: 736 | N19: 4.475748 | O19: 0.91370209
B20: Pay Freq | C20: Annual | E20: Pay Freq | F20: Annual | H20: SOFR Swap | I20: 5 Year | J20: 4.013 | L20: 46475 | M20: 1103 | N20: 4.1893785 | O20: 0.88108641
B21: Reset Freq | E21: Reset Freq | F21: Annual | H21: SOFR Swap | I21: 6 Year | J21: 3.9636 | L21: 46841 | M21: 1469 | N21: 4.0565905 | O21: 0.84936703
H22: SOFR Swap | I22: 7 Year | J22: 3.9324 | L22: 47205 | M22: 1833 | N22: 3.9668193 | O22: 0.81937747
B23: Value | C23: -17980613 | E23: Value | F23: 17980613 | H23: SOFR Swap | I23: 8 Year | J23: 3.9175 | L23: 47569 | M23: 2197 | N23: 3.9176375 | O23: 0.78993108
H24: SOFR Swap | I24: 9 Year | J24: 3.9021 | L24: 47934 | M24: 2562 | N24: 3.8868557 | O24: 0.76122574
C25: Trade Value: | D25: 0.01 | H25: SOFR Swap | I25: 10 Year | J25: 3.8968 | L25: 48302 | M25: 2930 | N25: 3.8730307 | O25: 0.73278454
H26: SOFR Swap | I26: 12 Year | J26: 3.9003 | L26: 48667 | M26: 3295 | N26: 3.8580199 | O26: 0.70590206
H27: SOFR Swap | I27: 15 Year | J27: 3.9094 | L27: 49032 | M27: 3660 | N27: 3.854134 | O27: 0.67945157
H28: SOFR Swap | I28: 20 Year | J28: 3.8804 | L28: 49761 | M28: 4389 | N28: 3.8618232 | O28: 0.62853032
H29: SOFR Swap | I29: 25 Year | J29: 3.7993 | L29: 50858 | M29: 5486 | N29: 3.8762293 | O29: 0.55844308
H30: SOFR Swap | I30: 30 Year | J30: 3.701 | L30: 52685 | M30: 7313 | N30: 3.8389018 | O30: 0.46340789
L31: 54511 | M31: 9139 | N31: 3.7229459 | O31: 0.39370064
L32: 56335 | M32: 10963 | N32: 3.5759801 | O32: 0.34161611

Sheet GIRR Delta Aggregations
B2: Sensitivities
B4: FRTB Tenors | C4: Sensitivities
B5: 3M | C5: -109.5
B6: 6M | C6: -1.81
B7: 1Y | C7: 387.24
B8: 2Y | C8: 652.5
B9: 3Y | C9: 1648.89
B10: 5Y | C10: 43664.52
B11: 10Y | C11: 24.75
B12: 15Y | C12: -0.45
B13: 20Y
B14: 30Y
B16: Total | C16: =IF('Consolidated View'!$C$2="Lite",SQRT(ABS(C17)),SQRT(IF(C17>0,C17,C18))) -> 4964393.6
B17: Reg^2 | C17: =SUMSQ($E$21:$E$21)+MAX(-1,MIN(1,'BIS Data'!$H$6*'BIS Data'!$H$5))*SUM($F$21:$F$21) -> 2.4645204e+13
B18: Alt^2 | C18: =SUMSQ($E$21:$E$21)+MAX(-1,MIN(1,'BIS Data'!$H$6*'BIS Data'!$H$5))*SUM($G$21:$G$21) -> 2.4645204e+13
K19: Correlations
B20: Ccy | C20: S_b Reg | D20: S_b Alt | E20: K_b | F20: Temp Reg | G20: Temp Alt | K20: =OFFSET($B$24,COLUMN()-COLUMN($K20),0) -> USD | L20: =OFFSET($B$24,COLUMN()-COLUMN($K20),0) -> USD | M20: =OFFSET($B$24,COLUMN()-COLUMN($K20),0) -> USD | N20: =OFFSET($B$24,COLUMN()-COLUMN($K20),0) -> USD | O20: =OFFSET($B$24,COLUMN()-COLUMN($K20),0) -> USD | P20: =OFFSET($B$24,COLUMN()-COLUMN($K20),0) -> USD | Q20: =OFFSET($B$24,COLUMN()-COLUMN($K20),0) -> USD | R20: =OFFSET($B$24,COLUMN()-COLUMN($K20),0) -> USD
B21: USD | C21: =SUMIF($B$24:$B$158,"="&B21,$G$24:$G$158) -> 4965067.3 | D21: =MAX(MIN(C21,E21),-E21) -> 4964393.6 | E21: =SQRT(MAX(SUMIF($B$24:$B$158,"="&B21,$H$24:$H$158)+SUMIF($B$24:$B$158,"="&B21,$I$24:$I$158),0)) -> 4964393.6 | F21: =C21*SUMIF($B$21:$B$21,"<>"&B21,$C$21:$C$21) -> 0 | G21: =C21*SUMIF($B$21:$B$21,"<>"&B21,$D$21:$D$21) -> 0 | K21: =OFFSET($B$24,COLUMN()-COLUMN($K$21),1) -> SOFR | L21: =OFFSET($B$24,COLUMN()-COLUMN($K$21),1) -> SOFR | M21: =OFFSET($B$24,COLUMN()-COLUMN($K$21),1) -> SOFR | N21: =OFFSET($B$24,COLUMN()-COLUMN($K$21),1) -> SOFR | O21: =OFFSET($B$24,COLUMN()-COLUMN($K$21),1) -> SOFR | P21: =OFFSET($B$24,COLUMN()-COLUMN($K$21),1) -> SOFR | Q21: =OFFSET($B$24,COLUMN()-COLUMN($K$21),1) -> SOFR | R21: =OFFSET($B$24,COLUMN()-COLUMN($K$21),1) -> SOFR
K22: =OFFSET($B$24,COLUMN()-COLUMN($K$22),2) -> 0.25 | L22: =OFFSET($B$24,COLUMN()-COLUMN($K$22),2) -> 0.5 | M22: =OFFSET($B$24,COLUMN()-COLUMN($K$22),2) -> 1 | N22: =OFFSET($B$24,COLUMN()-COLUMN($K$22),2) -> 2 | O22: =OFFSET($B$24,COLUMN()-COLUMN($K$22),2) -> 3 | P22: =OFFSET($B$24,COLUMN()-COLUMN($K$22),2) -> 5 | Q22: =OFFSET($B$24,COLUMN()-COLUMN($K$22),2) -> 10 | R22: =OFFSET($B$24,COLUMN()-COLUMN($K$22),2) -> 15
B23: Ccy | C23: Index | D23: Tenor | E23: Scaled Sens | F23: RW_k | G23: WS_k | H23: WS_k^2 | I23: Sum Corr Values | K23: =OFFSET($B$24,COLUMN()-COLUMN($K$23),5) -> -18582.766 | L23: =OFFSET($B$24,COLUMN()-COLUMN($K$23),5) -> -307.16719 | M23: =OFFSET($B$24,COLUMN()-COLUMN($K$23),5) -> 61609.507 | N23: =OFFSET($B$24,COLUMN()-COLUMN($K$23),5) -> 86740.789 | O23: =OFFSET($B$24,COLUMN()-COLUMN($K$23),5) -> 201707.84 | P23: =OFFSET($B$24,COLUMN()-COLUMN($K$23),5) -> 4631321.7 | Q23: =OFFSET($B$24,COLUMN()-COLUMN($K$23),5) -> 2625.1339 | R23: =OFFSET($B$24,COLUMN()-COLUMN($K$23),5) -> -47.729708
B24: ='Pivot Data'!B4 -> USD | C24: ='Pivot Data'!C4 -> SOFR | D24: ='Pivot Data'!D4 -> 0.25 | E24: ='Pivot Data'!E4 -> -1095000 | F24: =IF(ISNUMBER(MATCH(B24,'BIS Data'!$L$3:$L$10,0)),1/'BIS Data'!$H$8,1)*VLOOKUP(D24,'BIS Data'!$B$3:$C$14,2,0) -> 0.016970563 | G24: =F24*E24 -> -18582.766 | H24: =G24*G24 -> 3.453192e+08 | I24: =SUM(K26:VI26) -> 2.6901443e+11 | K24: =K$23*$G24*MAX(-1,MIN(1,'BIS Data'!$H$5*IF(OR($C24&$D24=K$21&K$22,$B24<>K$20),0,OFFSET('BIS Data'!$B$17,MATCH($D24,'BIS Data'!$B$18:$B$27,0),MATCH(K$22,'BIS Data'!$C$17:$L$17,0))))) -> 0 | L24: =L$23*$G24*MAX(-1,MIN(1,'BIS Data'!$H$5*IF(OR($C24&$D24=L$21&L$22,$B24<>L$20),0,OFFSET('BIS Data'!$B$17,MATCH($D24,'BIS Data'!$B$18:$B$27,0),MATCH(L$22,'BIS Data'!$C$17:$L$17,0))))) -> 5539318.6 | M24: =M$23*$G24*MAX(-1,MIN(1,'BIS Data'!$H$5*IF(OR($C24&$D24=M$21&M$22,$B24<>M$20),0,OFFSET('BIS Data'!$B$17,MATCH($D24,'BIS Data'!$B$18:$B$27,0),MATCH(M$22,'BIS Data'!$C$17:$L$17,0))))) -> -1.046337e+09 | N24: =N$23*$G24*MAX(-1,MIN(1,'BIS Data'!$H$5*IF(OR($C24&$D24=N$21&N$22,$B24<>N$20),0,OFFSET('BIS Data'!$B$17,MATCH($D24,'BIS Data'!$B$18:$B$27,0),MATCH(N$22,'BIS Data'!$C$17:$L$17,0))))) -> -1.3065676e+09 | O24: =O$23*$G24*MAX(-1,MIN(1,'BIS Data'!$H$5*IF(OR($C24&$D24=O$21&O$22,$B24<>O$20),0,OFFSET('BIS Data'!$B$17,MATCH($D24,'BIS Data'!$B$18:$B$27,0),MATCH(O$22,'BIS Data'!$C$17:$L$17,0))))) -> -2.6947344e+09 | P24: =P$23*$G24*MAX(-1,MIN(1,'BIS Data'!$H$5*IF(OR($C24&$D24=P$21&P$22,$B24<>P$20),0,OFFSET('BIS Data'!$B$17,MATCH($D24,'BIS Data'!$B$18:$B$27,0),MATCH(P$22,'BIS Data'!$C$17:$L$17,0))))) -> -4.8670685e+10 | Q24: =Q$23*$G24*MAX(-1,MIN(1,'BIS Data'!$H$5*IF(OR($C24&$D24=Q$21&Q$22,$B24<>Q$20),0,OFFSET('BIS Data'!$B$17,MATCH($D24,'BIS Data'!$B$18:$B$27,0),MATCH(Q$22,'BIS Data'!$C$17:$L$17,0))))) -> -19512900 | R24: =R$23*$G24*MAX(-1,MIN(1,'BIS Data'!$H$5*IF(OR($C24&$D24=R$21&R$22,$B24<>R$20),0,OFFSET('BIS Data'!$B$17,MATCH($D24,'BIS Data'!$B$18:$B$27,0),MATCH(R$22,'BIS Data'!$C$17:$L$17,0))))) -> 354780
B25: ='Pivot Data'!B5 -> USD | C25: ='Pivot Data'!C5 -> SOFR | D25: ='Pivot Data'!D5 -> 0.5 | E25: ='Pivot Data'!E5 -> -18100 | F25: =IF(ISNUMBER(MATCH(B25,'BIS Data'!$L$3:$L$10,0)),1/'BIS Data'!$H$8,1)*VLOOKUP(D25,'BIS Data'!$B$3:$C$14,2,0) -> 0.016970563 | G25: =F25*E25 -> -307.16719 | H25: =G25*G25 -> 94351.68 | I25: =SUM(K27:VI27) -> 4.0533717e+11 | K25: =K$23*$G25*MAX(-1,MIN(1,'BIS Data'!$H$5*IF(OR($C25&$D25=K$21&K$22,$B25<>K$20),0,OFFSET('BIS Data'!$B$17,MATCH($D25,'BIS Data'!$B$18:$B$27,0),MATCH(K$22,'BIS Data'!$C$17:$L$17,0))))) -> 5539318.6 | L25: =L$23*$G25*MAX(-1,MIN(1,'BIS Data'!$H$5*IF(OR($C25&$D25=L$21&L$22,$B25<>L$20),0,OFFSET('BIS Data'!$B$17,MATCH($D25,'BIS Data'!$B$18:$B$27,0),MATCH(L$22,'BIS Data'!$C$17:$L$17,0))))) -> 0 | M25: =M$23*$G25*MAX(-1,MIN(1,'BIS Data'!$H$5*IF(OR($C25&$D25=M$21&M$22,$B25<>M$20),0,OFFSET('BIS Data'!$B$17,MATCH($D25,'BIS Data'!$B$18:$B$27,0),MATCH(M$22,'BIS Data'!$C$17:$L$17,0))))) -> -18365118 | N25: =N$23*$G25*MAX(-1,MIN(1,'BIS Data'!$H$5*IF(OR($C25&$D25=N$21&N$22,$B25<>N$20),0,OFFSET('BIS Data'!$B$17,MATCH($D25,'BIS Data'!$B$18:$B$27,0),MATCH(N$22,'BIS Data'!$C$17:$L$17,0))))) -> -24350713 | O25: =O$23*$G25*MAX(-1,MIN(1,'BIS Data'!$H$5*IF(OR($C25&$D25=O$21&O$22,$B25<>O$20),0,OFFSET('BIS Data'!$B$17,MATCH($D25,'BIS Data'!$B$18:$B$27,0),MATCH(O$22,'BIS Data'!$C$17:$L$17,0))))) -> -53327772 | P25: =P$23*$G25*MAX(-1,MIN(1,'BIS Data'!$H$5*IF(OR($C25&$D25=P$21&P$22,$B25<>P$20),0,OFFSET('BIS Data'!$B$17,MATCH($D25,'BIS Data'!$B$18:$B$27,0),MATCH(P$22,'BIS Data'!$C$17:$L$17,0))))) -> -1.0859761e+09 | Q25: =Q$23*$G25*MAX(-1,MIN(1,'BIS Data'!$H$5*IF(OR($C25&$D25=Q$21&Q$22,$B25<>Q$20),0,OFFSET('BIS Data'!$B$17,MATCH($D25,'BIS Data'!$B$18:$B$27,0),MATCH(Q$22,'BIS Data'!$C$17:$L$17,0))))) -> -456014.27 | R25: =R$23*$G25*MAX(-1,MIN(1,'BIS Data'!$H$5*IF(OR($C25&$D25=R$21&R$22,$B25<>R$20),0,OFFSET('BIS Data'!$B$17,MATCH($D25,'BIS Data'!$B$18:$B$27,0),MATCH(R$22,'BIS Data'!$C$17:$L$17,0))))) -> 6142.2487
B26: ='Pivot Data'!B6 -> USD | C26: ='Pivot Data'!C6 -> SOFR | D26: ='Pivot Data'!D6 -> 1 | E26: ='Pivot Data'!E6 -> 3872400 | F26: =IF(ISNUMBER(MATCH(B26,'BIS Data'!$L$3:$L$10,0)),1/'BIS Data'!$H$8,1)*VLOOKUP(D26,'BIS Data'!$B$3:$C$14,2,0) -> 0.015909903 | G26: =F26*E26 -> 61609.507 | H26: =G26*G26 -> 3.7957313e+09 | I26: =SUM(K28:VI28) -> 9.4235239e+11 | K26: =K$23*$G26*MAX(-1,MIN(1,'BIS Data'!$H$5*IF(OR($C26&$D26=K$21&K$22,$B26<>K$20),0,OFFSET('BIS Data'!$B$17,MATCH($D26,'BIS Data'!$B$18:$B$27,0),MATCH(K$22,'BIS Data'!$C$17:$L$17,0))))) -> -1.046337e+09 | L26: =L$23*$G26*MAX(-1,MIN(1,'BIS Data'!$H$5*IF(OR($C26&$D26=L$21&L$22,$B26<>L$20),0,OFFSET('BIS Data'!$B$17,MATCH($D26,'BIS Data'!$B$18:$B$27,0),MATCH(L$22,'BIS Data'!$C$17:$L$17,0))))) -> -18365118 | M26: =M$23*$G26*MAX(-1,MIN(1,'BIS Data'!$H$5*IF(OR($C26&$D26=M$21&M$22,$B26<>M$20),0,OFFSET('BIS Data'!$B$17,MATCH($D26,'BIS Data'!$B$18:$B$27,0),MATCH(M$22,'BIS Data'!$C$17:$L$17,0))))) -> 0 | N26: =N$23*$G26*MAX(-1,MIN(1,'BIS Data'!$H$5*IF(OR($C26&$D26=N$21&N$22,$B26<>N$20),0,OFFSET('BIS Data'!$B$17,MATCH($D26,'BIS Data'!$B$18:$B$27,0),MATCH(N$22,'BIS Data'!$C$17:$L$17,0))))) -> 5.1861165e+09 | O26: =O$23*$G26*MAX(-1,MIN(1,'BIS Data'!$H$5*IF(OR($C26&$D26=O$21&O$22,$B26<>O$20),0,OFFSET('BIS Data'!$B$17,MATCH($D26,'BIS Data'!$B$18:$B$27,0),MATCH(O$22,'BIS Data'!$C$17:$L$17,0))))) -> 1.1703422e+10 | P26: =P$23*$G26*MAX(-1,MIN(1,'BIS Data'!$H$5*IF(OR($C26&$D26=P$21&P$22,$B26<>P$20),0,OFFSET('BIS Data'!$B$17,MATCH($D26,'BIS Data'!$B$18:$B$27,0),MATCH(P$22,'BIS Data'!$C$17:$L$17,0))))) -> 2.5306807e+11 | Q26: =Q$23*$G26*MAX(-1,MIN(1,'BIS Data'!$H$5*IF(OR($C26&$D26=Q$21&Q$22,$B26<>Q$20),0,OFFSET('BIS Data'!$B$17,MATCH($D26,'BIS Data'!$B$18:$B$27,0),MATCH(Q$22,'BIS Data'!$C$17:$L$17,0))))) -> 1.2346381e+08 | R26: =R$23*$G26*MAX(-1,MIN(1,'BIS Data'!$H$5*IF(OR($C26&$D26=R$21&R$22,$B26<>R$20),0,OFFSET('BIS Data'!$B$17,MATCH($D26,'BIS Data'!$B$18:$B$27,0),MATCH(R$22,'BIS Data'!$C$17:$L$17,0))))) -> -1932114.3
B27: ='Pivot Data'!B7 -> USD | C27: ='Pivot Data'!C7 -> SOFR | D27: ='Pivot Data'!D7 -> 2 | E27: ='Pivot Data'!E7 -> 6525000 | F27: =IF(ISNUMBER(MATCH(B27,'BIS Data'!$L$3:$L$10,0)),1/'BIS Data'!$H$8,1)*VLOOKUP(D27,'BIS Data'!$B$3:$C$14,2,0) -> 0.013293607 | G27: =F27*E27 -> 86740.789 | H27: =G27*G27 -> 7.5239644e+09 | I27: =SUM(K29:VI29) -> 1.5146254e+12 | K27: =K$23*$G27*MAX(-1,MIN(1,'BIS Data'!$H$5*IF(OR($C27&$D27=K$21&K$22,$B27<>K$20),0,OFFSET('BIS Data'!$B$17,MATCH($D27,'BIS Data'!$B$18:$B$27,0),MATCH(K$22,'BIS Data'!$C$17:$L$17,0))))) -> -1.3065676e+09 | L27: =L$23*$G27*MAX(-1,MIN(1,'BIS Data'!$H$5*IF(OR($C27&$D27=L$21&L$22,$B27<>L$20),0,OFFSET('BIS Data'!$B$17,MATCH($D27,'BIS Data'!$B$18:$B$27,0),MATCH(L$22,'BIS Data'!$C$17:$L$17,0))))) -> -24350713 | M27: =M$23*$G27*MAX(-1,MIN(1,'BIS Data'!$H$5*IF(OR($C27&$D27=M$21&M$22,$B27<>M$20),0,OFFSET('BIS Data'!$B$17,MATCH($D27,'BIS Data'!$B$18:$B$27,0),MATCH(M$22,'BIS Data'!$C$17:$L$17,0))))) -> 5.1861165e+09 | N27: =N$23*$G27*MAX(-1,MIN(1,'BIS Data'!$H$5*IF(OR($C27&$D27=N$21&N$22,$B27<>N$20),0,OFFSET('BIS Data'!$B$17,MATCH($D27,'BIS Data'!$B$18:$B$27,0),MATCH(N$22,'BIS Data'!$C$17:$L$17,0))))) -> 0 | O27: =O$23*$G27*MAX(-1,MIN(1,'BIS Data'!$H$5*IF(OR($C27&$D27=O$21&O$22,$B27<>O$20),0,OFFSET('BIS Data'!$B$17,MATCH($D27,'BIS Data'!$B$18:$B$27,0),MATCH(O$22,'BIS Data'!$C$17:$L$17,0))))) -> 1.7235812e+10 | P27: =P$23*$G27*MAX(-1,MIN(1,'BIS Data'!$H$5*IF(OR($C27&$D27=P$21&P$22,$B27<>P$20),0,OFFSET('BIS Data'!$B$17,MATCH($D27,'BIS Data'!$B$18:$B$27,0),MATCH(P$22,'BIS Data'!$C$17:$L$17,0))))) -> 3.8404761e+11 | Q27: =Q$23*$G27*MAX(-1,MIN(1,'BIS Data'!$H$5*IF(OR($C27&$D27=Q$21&Q$22,$B27<>Q$20),0,OFFSET('BIS Data'!$B$17,MATCH($D27,'BIS Data'!$B$18:$B$27,0),MATCH(Q$22,'BIS Data'!$C$17:$L$17,0))))) -> 2.0195727e+08 | R27: =R$23*$G27*MAX(-1,MIN(1,'BIS Data'!$H$5*IF(OR($C27&$D27=R$21&R$22,$B27<>R$20),0,OFFSET('BIS Data'!$B$17,MATCH($D27,'BIS Data'!$B$18:$B$27,0),MATCH(R$22,'BIS Data'!$C$17:$L$17,0))))) -> -3406628.1
B28: ='Pivot Data'!B8 -> USD | C28: ='Pivot Data'!C8 -> SOFR | D28: ='Pivot Data'!D8 -> 3 | E28: ='Pivot Data'!E8 -> 16488900 | F28: =IF(ISNUMBER(MATCH(B28,'BIS Data'!$L$3:$L$10,0)),1/'BIS Data'!$H$8,1)*VLOOKUP(D28,'BIS Data'!$B$3:$C$14,2,0) -> 0.012232947 | G28: =F28*E28 -> 201707.84 | H28: =G28*G28 -> 4.0686055e+10 | I28: =SUM(K30:VI30) -> 1.2597562e+10 | K28: =K$23*$G28*MAX(-1,MIN(1,'BIS Data'!$H$5*IF(OR($C28&$D28=K$21&K$22,$B28<>K$20),0,OFFSET('BIS Data'!$B$17,MATCH($D28,'BIS Data'!$B$18:$B$27,0),MATCH(K$22,'BIS Data'!$C$17:$L$17,0))))) -> -2.6947344e+09 | L28: =L$23*$G28*MAX(-1,MIN(1,'BIS Data'!$H$5*IF(OR($C28&$D28=L$21&L$22,$B28<>L$20),0,OFFSET('BIS Data'!$B$17,MATCH($D28,'BIS Data'!$B$18:$B$27,0),MATCH(L$22,'BIS Data'!$C$17:$L$17,0))))) -> -53327772 | M28: =M$23*$G28*MAX(-1,MIN(1,'BIS Data'!$H$5*IF(OR($C28&$D28=M$21&M$22,$B28<>M$20),0,OFFSET('BIS Data'!$B$17,MATCH($D28,'BIS Data'!$B$18:$B$27,0),MATCH(M$22,'BIS Data'!$C$17:$L$17,0))))) -> 1.1703422e+10 | N28: =N$23*$G28*MAX(-1,MIN(1,'BIS Data'!$H$5*IF(OR($C28&$D28=N$21&N$22,$B28<>N$20),0,OFFSET('BIS Data'!$B$17,MATCH($D28,'BIS Data'!$B$18:$B$27,0),MATCH(N$22,'BIS Data'!$C$17:$L$17,0))))) -> 1.7235812e+10 | O28: =O$23*$G28*MAX(-1,MIN(1,'BIS Data'!$H$5*IF(OR($C28&$D28=O$21&O$22,$B28<>O$20),0,OFFSET('BIS Data'!$B$17,MATCH($D28,'BIS Data'!$B$18:$B$27,0),MATCH(O$22,'BIS Data'!$C$17:$L$17,0))))) -> 0 | P28: =P$23*$G28*MAX(-1,MIN(1,'BIS Data'!$H$5*IF(OR($C28&$D28=P$21&P$22,$B28<>P$20),0,OFFSET('BIS Data'!$B$17,MATCH($D28,'BIS Data'!$B$18:$B$27,0),MATCH(P$22,'BIS Data'!$C$17:$L$17,0))))) -> 9.1567604e+11 | Q28: =Q$23*$G28*MAX(-1,MIN(1,'BIS Data'!$H$5*IF(OR($C28&$D28=Q$21&Q$22,$B28<>Q$20),0,OFFSET('BIS Data'!$B$17,MATCH($D28,'BIS Data'!$B$18:$B$27,0),MATCH(Q$22,'BIS Data'!$C$17:$L$17,0))))) -> 4.9371195e+08 | R28: =R$23*$G28*MAX(-1,MIN(1,'BIS Data'!$H$5*IF(OR($C28&$D28=R$21&R$22,$B28<>R$20),0,OFFSET('BIS Data'!$B$17,MATCH($D28,'BIS Data'!$B$18:$B$27,0),MATCH(R$22,'BIS Data'!$C$17:$L$17,0))))) -> -8538787.9
B29: ='Pivot Data'!B9 -> USD | C29: ='Pivot Data'!C9 -> SOFR | D29: ='Pivot Data'!D9 -> 5 | E29: ='Pivot Data'!E9 -> 4.366452e+08 | F29: =IF(ISNUMBER(MATCH(B29,'BIS Data'!$L$3:$L$10,0)),1/'BIS Data'!$H$8,1)*VLOOKUP(D29,'BIS Data'!$B$3:$C$14,2,0) -> 0.010606602 | G29: =F29*E29 -> 4631321.7 | H29: =G29*G29 -> 2.1449141e+13 | I29: =SUM(K31:VI31) -> -2.2181863e+08 | K29: =K$23*$G29*MAX(-1,MIN(1,'BIS Data'!$H$5*IF(OR($C29&$D29=K$21&K$22,$B29<>K$20),0,OFFSET('BIS Data'!$B$17,MATCH($D29,'BIS Data'!$B$18:$B$27,0),MATCH(K$22,'BIS Data'!$C$17:$L$17,0))))) -> -4.8670685e+10 | L29: =L$23*$G29*MAX(-1,MIN(1,'BIS Data'!$H$5*IF(OR($C29&$D29=L$21&L$22,$B29<>L$20),0,OFFSET('BIS Data'!$B$17,MATCH($D29,'BIS Data'!$B$18:$B$27,0),MATCH(L$22,'BIS Data'!$C$17:$L$17,0))))) -> -1.0859761e+09 | M29: =M$23*$G29*MAX(-1,MIN(1,'BIS Data'!$H$5*IF(OR($C29&$D29=M$21&M$22,$B29<>M$20),0,OFFSET('BIS Data'!$B$17,MATCH($D29,'BIS Data'!$B$18:$B$27,0),MATCH(M$22,'BIS Data'!$C$17:$L$17,0))))) -> 2.5306807e+11 | N29: =N$23*$G29*MAX(-1,MIN(1,'BIS Data'!$H$5*IF(OR($C29&$D29=N$21&N$22,$B29<>N$20),0,OFFSET('BIS Data'!$B$17,MATCH($D29,'BIS Data'!$B$18:$B$27,0),MATCH(N$22,'BIS Data'!$C$17:$L$17,0))))) -> 3.8404761e+11 | O29: =O$23*$G29*MAX(-1,MIN(1,'BIS Data'!$H$5*IF(OR($C29&$D29=O$21&O$22,$B29<>O$20),0,OFFSET('BIS Data'!$B$17,MATCH($D29,'BIS Data'!$B$18:$B$27,0),MATCH(O$22,'BIS Data'!$C$17:$L$17,0))))) -> 9.1567604e+11 | P29: =P$23*$G29*MAX(-1,MIN(1,'BIS Data'!$H$5*IF(OR($C29&$D29=P$21&P$22,$B29<>P$20),0,OFFSET('BIS Data'!$B$17,MATCH($D29,'BIS Data'!$B$18:$B$27,0),MATCH(P$22,'BIS Data'!$C$17:$L$17,0))))) -> 0 | Q29: =Q$23*$G29*MAX(-1,MIN(1,'BIS Data'!$H$5*IF(OR($C29&$D29=Q$21&Q$22,$B29<>Q$20),0,OFFSET('BIS Data'!$B$17,MATCH($D29,'BIS Data'!$B$18:$B$27,0),MATCH(Q$22,'BIS Data'!$C$17:$L$17,0))))) -> 1.1798521e+10 | R29: =R$23*$G29*MAX(-1,MIN(1,'BIS Data'!$H$5*IF(OR($C29&$D29=R$21&R$22,$B29<>R$20),0,OFFSET('BIS Data'!$B$17,MATCH($D29,'BIS Data'!$B$18:$B$27,0),MATCH(R$22,'BIS Data'!$C$17:$L$17,0))))) -> -2.0817859e+08
B30: ='Pivot Data'!B10 -> USD | C30: ='Pivot Data'!C10 -> SOFR | D30: ='Pivot Data'!D10 -> 10 | E30: ='Pivot Data'!E10 -> 247500 | F30: =IF(ISNUMBER(MATCH(B30,'BIS Data'!$L$3:$L$10,0)),1/'BIS Data'!$H$8,1)*VLOOKUP(D30,'BIS Data'!$B$3:$C$14,2,0) -> 0.010606602 | G30: =F30*E30 -> 2625.1339 | H30: =G30*G30 -> 6891328.1 | I30: =SUM(K32:VI32) -> 0 | K30: =K$23*$G30*MAX(-1,MIN(1,'BIS Data'!$H$5*IF(OR($C30&$D30=K$21&K$22,$B30<>K$20),0,OFFSET('BIS Data'!$B$17,MATCH($D30,'BIS Data'!$B$18:$B$27,0),MATCH(K$22,'BIS Data'!$C$17:$L$17,0))))) -> -19512900 | L30: =L$23*$G30*MAX(-1,MIN(1,'BIS Data'!$H$5*IF(OR($C30&$D30=L$21&L$22,$B30<>L$20),0,OFFSET('BIS Data'!$B$17,MATCH($D30,'BIS Data'!$B$18:$B$27,0),MATCH(L$22,'BIS Data'!$C$17:$L$17,0))))) -> -456014.27 | M30: =M$23*$G30*MAX(-1,MIN(1,'BIS Data'!$H$5*IF(OR($C30&$D30=M$21&M$22,$B30<>M$20),0,OFFSET('BIS Data'!$B$17,MATCH($D30,'BIS Data'!$B$18:$B$27,0),MATCH(M$22,'BIS Data'!$C$17:$L$17,0))))) -> 1.2346381e+08 | N30: =N$23*$G30*MAX(-1,MIN(1,'BIS Data'!$H$5*IF(OR($C30&$D30=N$21&N$22,$B30<>N$20),0,OFFSET('BIS Data'!$B$17,MATCH($D30,'BIS Data'!$B$18:$B$27,0),MATCH(N$22,'BIS Data'!$C$17:$L$17,0))))) -> 2.0195727e+08 | O30: =O$23*$G30*MAX(-1,MIN(1,'BIS Data'!$H$5*IF(OR($C30&$D30=O$21&O$22,$B30<>O$20),0,OFFSET('BIS Data'!$B$17,MATCH($D30,'BIS Data'!$B$18:$B$27,0),MATCH(O$22,'BIS Data'!$C$17:$L$17,0))))) -> 4.9371195e+08 | P30: =P$23*$G30*MAX(-1,MIN(1,'BIS Data'!$H$5*IF(OR($C30&$D30=P$21&P$22,$B30<>P$20),0,OFFSET('BIS Data'!$B$17,MATCH($D30,'BIS Data'!$B$18:$B$27,0),MATCH(P$22,'BIS Data'!$C$17:$L$17,0))))) -> 1.1798521e+10 | Q30: =Q$23*$G30*MAX(-1,MIN(1,'BIS Data'!$H$5*IF(OR($C30&$D30=Q$21&Q$22,$B30<>Q$20),0,OFFSET('BIS Data'!$B$17,MATCH($D30,'BIS Data'!$B$18:$B$27,0),MATCH(Q$22,'BIS Data'!$C$17:$L$17,0))))) -> 0 | R30: =R$23*$G30*MAX(-1,MIN(1,'BIS Data'!$H$5*IF(OR($C30&$D30=R$21&R$22,$B30<>R$20),0,OFFSET('BIS Data'!$B$17,MATCH($D30,'BIS Data'!$B$18:$B$27,0),MATCH(R$22,'BIS Data'!$C$17:$L$17,0))))) -> -123431.45
B31: ='Pivot Data'!B11 -> USD | C31: ='Pivot Data'!C11 -> SOFR | D31: ='Pivot Data'!D11 -> 15 | E31: ='Pivot Data'!E11 -> -4500 | F31: =IF(ISNUMBER(MATCH(B31,'BIS Data'!$L$3:$L$10,0)),1/'BIS Data'!$H$8,1)*VLOOKUP(D31,'BIS Data'!$B$3:$C$14,2,0) -> 0.010606602 | G31: =F31*E31 -> -47.729708 | H31: =G31*G31 -> 2278.125 | I31: =SUM(K33:VI33) -> 0 | K31: =K$23*$G31*MAX(-1,MIN(1,'BIS Data'!$H$5*IF(OR($C31&$D31=K$21&K$22,$B31<>K$20),0,OFFSET('BIS Data'!$B$17,MATCH($D31,'BIS Data'!$B$18:$B$27,0),MATCH(K$22,'BIS Data'!$C$17:$L$17,0))))) -> 354780 | L31: =L$23*$G31*MAX(-1,MIN(1,'BIS Data'!$H$5*IF(OR($C31&$D31=L$21&L$22,$B31<>L$20),0,OFFSET('BIS Data'!$B$17,MATCH($D31,'BIS Data'!$B$18:$B$27,0),MATCH(L$22,'BIS Data'!$C$17:$L$17,0))))) -> 6142.2487 | M31: =M$23*$G31*MAX(-1,MIN(1,'BIS Data'!$H$5*IF(OR($C31&$D31=M$21&M$22,$B31<>M$20),0,OFFSET('BIS Data'!$B$17,MATCH($D31,'BIS Data'!$B$18:$B$27,0),MATCH(M$22,'BIS Data'!$C$17:$L$17,0))))) -> -1932114.3 | N31: =N$23*$G31*MAX(-1,MIN(1,'BIS Data'!$H$5*IF(OR($C31&$D31=N$21&N$22,$B31<>N$20),0,OFFSET('BIS Data'!$B$17,MATCH($D31,'BIS Data'!$B$18:$B$27,0),MATCH(N$22,'BIS Data'!$C$17:$L$17,0))))) -> -3406628.1 | O31: =O$23*$G31*MAX(-1,MIN(1,'BIS Data'!$H$5*IF(OR($C31&$D31=O$21&O$22,$B31<>O$20),0,OFFSET('BIS Data'!$B$17,MATCH($D31,'BIS Data'!$B$18:$B$27,0),MATCH(O$22,'BIS Data'!$C$17:$L$17,0))))) -> -8538787.9 | P31: =P$23*$G31*MAX(-1,MIN(1,'BIS Data'!$H$5*IF(OR($C31&$D31=P$21&P$22,$B31<>P$20),0,OFFSET('BIS Data'!$B$17,MATCH($D31,'BIS Data'!$B$18:$B$27,0),MATCH(P$22,'BIS Data'!$C$17:$L$17,0))))) -> -2.0817859e+08 | Q31: =Q$23*$G31*MAX(-1,MIN(1,'BIS Data'!$H$5*IF(OR($C31&$D31=Q$21&Q$22,$B31<>Q$20),0,OFFSET('BIS Data'!$B$17,MATCH($D31,'BIS Data'!$B$18:$B$27,0),MATCH(Q$22,'BIS Data'!$C$17:$L$17,0))))) -> -123431.45 | R31: =R$23*$G31*MAX(-1,MIN(1,'BIS Data'!$H$5*IF(OR($C31&$D31=R$21&R$22,$B31<>R$20),0,OFFSET('BIS Data'!$B$17,MATCH($D31,'BIS Data'!$B$18:$B$27,0),MATCH(R$22,'BIS Data'!$C$17:$L$17,0))))) -> 0

Sheet Trading System Data
A1: Position Id | B1: Type | C1: Ccy | D1: Index | E1: Tenor | F1: Shift (bp) | G1: Amount | H1: Scaled Amount
A2: Swap1 | B2: Interest Rate | C2: USD | D2: SOFR | E2: 0.25 | F2: 1 | G2: -109.5 | H2: =G2/(F2/10000) -> -1095000 | J2: Amount and Scaled Amount can be modified
A3: Swap1 | B3: Interest Rate | C3: USD | D3: SOFR | E3: 0.5 | F3: 1 | G3: -1.81 | H3: =G3/(F3/10000) -> -18100
A4: Swap1 | B4: Interest Rate | C4: USD | D4: SOFR | E4: 1 | F4: 1 | G4: 387.24 | H4: =G4/(F4/10000) -> 3872400 | J4: Portfolio of trades is stored here and then
A5: Swap1 | B5: Interest Rate | C5: USD | D5: SOFR | E5: 2 | F5: 1 | G5: 652.5 | H5: =G5/(F5/10000) -> 6525000 | J5: consolidated in pivot tables in next tab
A6: Swap1 | B6: Interest Rate | C6: USD | D6: SOFR | E6: 3 | F6: 1 | G6: 1648.89 | H6: =G6/(F6/10000) -> 16488900
A7: Swap1 | B7: Interest Rate | C7: USD | D7: SOFR | E7: 5 | F7: 1 | G7: 43664.52 | H7: =G7/(F7/10000) -> 4.366452e+08
A8: Swap1 | B8: Interest Rate | C8: USD | D8: SOFR | E8: 10 | F8: 1 | G8: 24.75 | H8: =G8/(F8/10000) -> 247500
A9: Swap1 | B9: Interest Rate | C9: USD | D9: SOFR | E9: 15 | F9: 1 | G9: -0.45 | H9: =G9/(F9/10000) -> -4500

Sheet Pivot Data
B3: Ccy | C3: Index | D3: Tenor | E3: Sum of Scaled Amount
B4: USD | C4: SOFR | D4: 0.25 | E4: -1095000
B5: USD | C5: SOFR | D5: 0.5 | E5: -18100
B6: USD | C6: SOFR | D6: 1 | E6: 3872400
B7: USD | C7: SOFR | D7: 2 | E7: 6525000
B8: USD | C8: SOFR | D8: 3 | E8: 16488900
B9: USD | C9: SOFR | D9: 5 | E9: 4.366452e+08
B10: USD | C10: SOFR | D10: 10 | E10: 247500
B11: USD | C11: SOFR | D11: 15 | E11: -4500

Sheet Misc
B2: Correlation Scenarios
B3: Low
B4: Medium
B5: High
B6: Lite
